<?xml version="1.0"?>
<robot name="iiwa7">

  <material name="Orange">
    <color rgba="1 0.423 0.039 1.0"/>
  </material>

<material name="Grey">
  <color rgba="0.4 0.4 0.4 1.0"/>
</material>

<link name="world" />

  <!-- Joint between world and link_0 -->
  <joint name="world_iiwa7_joint" type="fixed">
    <origin xyz="0 0 0" rpy="0 0 0"/>
    <parent link="world"/>
    <child link="iiwa7_link_0"/>
  </joint>

  <!-- Link 0 -->
  <link name="iiwa7_link_0">
    <inertial>
      <origin xyz="-0.1 0 0.07" rpy="0 0 0"/>
      <mass value="5"/>
      <inertia ixx="0.05"  ixy="0"  ixz="0" iyy="0.06" iyz="0" izz="0.03"/>
    </inertial>
    <visual>
      <origin xyz="0 0 0" rpy="0 0 0"/>
      <geometry>
        <mesh filename="../meshes/visual/link_0.stl"/>
      </geometry>
      <material name="Grey"/>
    </visual>
    <collision>
      <origin xyz="0 0 0" rpy="0 0 0"/>
      <geometry>
        <mesh filename="../meshes/collision/link_0.stl"/>
      </geometry>
      <material name="Grey"/>
    </collision>
  </link>

  <!-- Joint 1 -->
  <joint name="iiwa7_joint_1" type="revolute">
    <parent link="iiwa7_link_0"/>
    <child link="iiwa7_link_1"/>
    <origin xyz="0 0 0.15" rpy="0 0 0"/>
    <axis xyz="0 0 1"/>
    <limit lower="-2.96705972839036" upper="2.96705972839036" effort="300" velocity="10"/>
    <safety_controller soft_lower_limit="-2.93215314335047" soft_upper_limit="2.93215314335047" k_position="100" k_velocity="2"/>
    <dynamics damping="0.5"/>
  </joint>

  <!-- Link 1 -->
  <link name="iiwa7_link_1">
    <inertial>
      <origin xyz="0 -0.03 0.12" rpy="0 0 0"/>
      <mass value="3.4525"/>
      <inertia ixx="0.02183" ixy="0" ixz="0" iyy="0.007703" iyz="-0.003887" izz="0.02083"/>
    </inertial>
    <visual>
      <origin xyz="0 0 0.0075" rpy="0 0 0"/>
      <geometry>
        <mesh filename="../meshes/visual/link_1.stl"/>
      </geometry>
      <material name="Orange"/>
    </visual>
    <collision>
      <origin xyz="0 0 0.0075" rpy="0 0 0"/>
      <geometry>
        <mesh filename="../meshes/collision/link_1.stl"/>
      </geometry>
      <material name="Orange"/>
    </collision>
  </link>

  <!-- Joint 2 -->
  <joint name="iiwa7_joint_2" type="revolute">
    <parent link="iiwa7_link_1"/>
    <child link="iiwa7_link_2"/>
    <origin xyz="0 0 0.19" rpy="1.5707963267949 0 3.14159265358979"/>
    <axis xyz="0 0 1"/>
    <limit lower="-2.0943951023932" upper="2.0943951023932" effort="300" velocity="10"/>
    <safety_controller soft_lower_limit="-2.05948851735331" soft_upper_limit="2.05948851735331" k_position="100" k_velocity="2"/>
    <dynamics damping="0.5"/>
  </joint>

  <!-- Link 2 -->
  <link name="iiwa7_link_2">
    <inertial>
      <origin xyz="0.0003 0.059 0.042" rpy="0 0 0"/>
      <mass value="3.4821"/>
      <inertia ixx="0.02076" ixy="0" ixz="-0.003626" iyy="0.02179" iyz="0" izz="0.00779"/>
    </inertial>
    <visual>
      <origin xyz="0 0 0" rpy="0 0 0"/>
      <geometry>
        <mesh filename="../meshes/visual/link_2.stl"/>
      </geometry>
      <material name="Orange"/>
    </visual>
    <collision>
      <origin xyz="0 0 0" rpy="0 0 0"/>
      <geometry>
        <mesh filename="../meshes/collision/link_2.stl"/>
      </geometry>
      <material name="Orange"/>
    </collision>
  </link>

  <!-- Joint 3 -->
  <joint name="iiwa7_joint_3" type="revolute">
    <parent link="iiwa7_link_2"/>
    <child link="iiwa7_link_3"/>
    <origin xyz="0 0.21 0" rpy="1.5707963267949 0 3.14159265358979"/>
    <axis xyz="0 0 1"/>
    <limit lower="-2.96705972839036" upper="2.96705972839036" effort="300" velocity="10"/>
    <safety_controller soft_lower_limit="-2.93215314335047" soft_upper_limit="2.93215314335047" k_position="100" k_velocity="2"/>
    <dynamics damping="0.5"/>
  </joint>

  <!-- Link 3 -->
  <link name="iiwa7_link_3">
    <inertial>
      <origin xyz="0 0.03 0.13" rpy="0 0 0"/>
      <mass value="4.05623"/>
      <inertia ixx="0.03204" ixy="0" ixz="0" iyy="0.00972" iyz="0.006227" izz="0.03042"/>
    </inertial>
    <visual>
      <origin xyz="0 0 -0.026" rpy="0 0 0"/>
      <geometry>
        <mesh filename="../meshes/visual/link_3.stl"/>
      </geometry>
      <material name="Orange"/>
    </visual>
    <collision>
      <origin xyz="0 0 -0.026" rpy="0 0 0"/>
      <geometry>
        <mesh filename="../meshes/collision/link_3.stl"/>
      </geometry>
      <material name="Orange"/>
    </collision>
  </link>

  <!-- Joint 4 -->
  <joint name="iiwa7_joint_4" type="revolute">
    <parent link="iiwa7_link_3"/>
    <child link="iiwa7_link_4"/>
    <origin xyz="0 0 0.19" rpy="1.5707963267949 0 0"/>
    <axis xyz="0 0 1"/>
    <limit lower="-2.0943951023932" upper="2.0943951023932" effort="300" velocity="10"/>
    <safety_controller soft_lower_limit="-2.05948851735331" soft_upper_limit="2.05948851735331" k_position="100" k_velocity="2"/>
    <dynamics damping="0.5"/>
  </joint>

  <!-- Link 4 -->
  <link name="iiwa7_link_4">
    <inertial>
      <origin xyz="0 0.067 0.034" rpy="0 0 0"/>
      <mass value="3.4822"/>
      <inertia ixx="0.02178" ixy="0" ixz="0" iyy="0.02075" iyz="-0.003625" izz="0.007785"/>
    </inertial>
    <visual>
      <origin xyz="0 0 0" rpy="0 0 0"/>
      <geometry>
        <mesh filename="../meshes/visual/link_4.stl"/>
      </geometry>
      <material name="Orange"/>
    </visual>
    <collision>
      <origin xyz="0 0 0" rpy="0 0 0"/>
      <geometry>
        <mesh filename="../meshes/collision/link_4.stl"/>
      </geometry>
      <material name="Orange"/>
    </collision>
  </link>

  <!-- Joint 5 -->
  <joint name="iiwa7_joint_5" type="revolute">
    <parent link="iiwa7_link_4"/>
    <child link="iiwa7_link_5"/>
    <origin xyz="0 0.21 0" rpy="-1.5707963267949 3.14159265358979 0"/>
    <axis xyz="0 0 1"/>
    <limit lower="-2.96705972839036" upper="2.96705972839036" effort="300" velocity="10"/>
    <safety_controller soft_lower_limit="-2.93215314335047" soft_upper_limit="2.93215314335047" k_position="100" k_velocity="2"/>
    <dynamics damping="0.5"/>
  </joint>

  <!-- Link 5 -->
  <link name="iiwa7_link_5">
    <inertial>
      <origin xyz="0.0001 0.021 0.076" rpy="0 0 0"/>
      <mass value="2.1633"/>
      <inertia ixx="0.01287" ixy="0" ixz="0" iyy="0.005708" iyz="-0.003946" izz="0.01112"/>
    </inertial>
    <visual>
      <origin xyz="0 0 -0.026" rpy="0 0 0"/>
      <geometry>
        <mesh filename="../meshes/visual/link_5.stl"/>
      </geometry>
      <material name="Orange"/>
    </visual>
    <collision>
      <origin xyz="0 0 -0.026" rpy="0 0 0"/>
      <geometry>
        <mesh filename="../meshes/collision/link_5.stl"/>
      </geometry>
      <material name="Orange"/>
    </collision>
  </link>

  <!-- Joint 6 -->
  <joint name="iiwa7_joint_6" type="revolute">
    <parent link="iiwa7_link_5"/>
    <child link="iiwa7_link_6"/>
    <origin xyz="0 0.06070 0.19" rpy="1.5707963267949 0 0"/>
    <axis xyz="0 0 1"/>
    <limit lower="-2.0943951023932" upper="2.0943951023932" effort="300" velocity="10"/>
    <safety_controller soft_lower_limit="-2.05948851735331" soft_upper_limit="2.05948851735331" k_position="100" k_velocity="2"/>
    <dynamics damping="0.5"/>
  </joint>

  <!-- Link 6 -->
  <link name="iiwa7_link_6">
    <inertial>
      <origin xyz="0 0.0006 0.0004" rpy="0 0 0"/>
      <mass value="2.3466"/>
      <inertia ixx="0.006509" ixy="0" ixz="0" iyy="0.006259" iyz="0.00031891" izz="0.004527"/>
    </inertial>
    <visual>
      <origin xyz="0 0 0" rpy="0 0 0"/>
      <geometry>
        <mesh filename="../meshes/visual/link_6.stl"/>
      </geometry>
      <material name="Orange"/>
    </visual>
    <collision>
      <origin xyz="0 0 0" rpy="0 0 0"/>
      <geometry>
        <mesh filename="../meshes/collision/link_6.stl"/>
      </geometry>
      <material name="Orange"/>
    </collision>
  </link>

  <!-- Joint 7 -->
  <joint name="iiwa7_joint_7" type="revolute">
    <parent link="iiwa7_link_6"/>
    <child link="iiwa7_link_7"/>
    <origin xyz="0 0.081 0.06070" rpy="-1.5707963267949 3.14159265358979 0"/>
    <axis xyz="0 0 1"/>
    <limit lower="-3.05432619099008" upper="3.05432619099008" effort="300" velocity="10"/>
    <safety_controller soft_lower_limit="-3.01941960595019" soft_upper_limit="3.01941960595019" k_position="100" k_velocity="2"/>
    <dynamics damping="0.5"/>
  </joint>

  <!-- Link 7 -->
  <link name="iiwa7_link_7">
    <inertial>
      <origin xyz="0 0 0.02" rpy="0 0 0"/>
      <mass value="3.129"/>
      <inertia ixx="0.01464" ixy="0.0005912" ixz="0" iyy="0.01465" iyz="0" izz="0.002872"/>
    </inertial>
    <visual>
      <origin xyz="0 0 -0.0005" rpy="0 0 0"/>
      <geometry>
        <mesh filename="../meshes/visual/link_7.stl"/>
      </geometry>
      <material name="Grey"/>
    </visual>
    <collision>
      <origin xyz="0 0 -0.0005" rpy="0 0 0"/>
      <geometry>
        <mesh filename="../meshes/collision/link_7.stl"/>
      </geometry>
      <material name="Grey"/>
    </collision>
  </link>

  <!-- End Effector Joint -->
  <joint name="iiwa7_joint_ee" type="fixed">
    <parent link="iiwa7_link_7"/>
    <child link="iiwa7_link_ee"/>
    <origin xyz="0 0 0.045" rpy="0 0 0"/>
  </joint>

  <!-- End Effector Link -->
  <link name="iiwa7_link_ee"/>
  
</robot>
